Workbook

Sheet Açıklama
A1: DöngüBorsa – Demir-Çelik Firma Analizi (v3 — Fiyatlandırma ve Etki Düzeltmesi)
A2: Sadece kullanılmamış / üretim fazlası malzeme — fiyatlandırma birincil malzeme referanslıdır
A5: DEĞİŞİKLİK 1 — FİYATLANDIRMA MANTIĞI:
A6: Önceki sürümde fiyatlar hurda/geri dönüşüm sitelerinden (hurdafiyatlari.tr vb.)
A7: alınıyordu — bu, 'eritilip yeniden işlenecek metal' değerini yansıtıyordu.
A8: Artık ürünlerimiz kullanılmamış üretim fazlası olduğu için, fiyatlandırma BİRİNCİL
A9: (prime) malzeme fiyatına dayanıyor:
A10: - DKP sac prime fiyatı: 37,50-40,00 TL/kg (sacfiyatlari.com.tr, ESN Metal)
A11: - Siyah/HRP sac prime fiyatı: 31,00-33,00 TL/kg (borufiyatlari.com.tr)
A12: - Kutu profil prime fiyatı: 27,00-30,00 TL/kg (LME Demir, celikfiyatlari.com)
A13: - Talaş/kırpıntı: 9,00-11,00 TL/kg (küçük parça formu nedeniyle düşük değerli;
A14: bu 'kullanılmış' olmasından değil, fiziksel formundan kaynaklanıyor)
... A37: 3) Ortalama_Hacimli_Firmalar -> IQR (Q1-Q3) aralığındaki firmalar + çevresel etki

Sheet Ham_Veri
A1: İşlem ID | B1: Firma ID | C1: Firma Adı | D1: Şehir | E1: Malzeme Türü | F1: Alt Tür | G1: Malzeme Durumu | H1: Paketleme Biçimi | I1: Prime Referans Fiyat (TL/kg) | J1: Miktar (kg) | K1: Birim Fiyat (TL/kg) | L1: Toplam Tutar (TL) | M1: İşlem Tarihi
A2: T-00001 | B2: F-1001 | C2: Firma 1001 San. Tic. Ltd. Şti. | D2: Gaziantep | E2: Demir-Çelik | F2: Kalıp Fazlası Parça | G2: Üretim Fazlası | H2: Gevşek | I2: 28.42 | J2: 931.9 | K2: 23.76 | L2: 22142 | M2: 2026-02-25
A3: T-00002 | B3: F-1001 | C3: Firma 1001 San. Tic. Ltd. Şti. | D3: Gaziantep | E3: Demir-Çelik | F3: Talaş / Kırpıntı | G3: Üretim Fazlası | H3: Preslenmiş-Balya | I3: 10.73 | J3: 1100.6 | K3: 9.91 | L3: 10906.63 | M3: 2025-08-28
A4: T-00003 | B4: F-1002 | C4: Firma 1002 San. Tic. Ltd. Şti. | D4: İstanbul | E4: Demir-Çelik | F4: DKP (Soğuk Haddelenmiş Sac Artığı) | G4: Kesim/İşleme Artığı | H4: Gevşek | I4: 37.98 | J4: 500 | K4: 27.06 | L4: 13530 | M4: 2026-05-02
A5: T-00004 | B5: F-1002 | C5: Firma 1002 San. Tic. Ltd. Şti. | D5: İstanbul | E5: Demir-Çelik | F5: Standart Dışı Sac / Levha | G5: Temiz | H5: Gevşek | I5: 31.93 | J5: 300 | K5: 27.9 | L5: 8370 | M5: 2025-09-08
A6: T-00005 | B6: F-1003 | C6: Firma 1003 San. Tic. Ltd. Şti. | D6: İstanbul | E6: Demir-Çelik | F6: Kalıp Fazlası Parça | G6: Temiz | H6: Preslenmiş-Balya | I6: 28.62 | J6: 3332.6 | K6: 27.65 | L6: 92145.22 | M6: 2025-08-08
A7: T-00006 | B7: F-1003 | C7: Firma 1003 San. Tic. Ltd. Şti. | D7: İstanbul | E7: Demir-Çelik | F7: DKP (Soğuk Haddelenmiş Sac Artığı) | G7: Temiz | H7: Preslenmiş-Balya | I7: 38.03 | J7: 4196 | K7: 36.74 | L7: 154162.67 | M7: 2026-02-22
A8: T-00007 | B8: F-1004 | C8: Firma 1004 San. Tic. Ltd. Şti. | D8: İstanbul | E8: Demir-Çelik | F8: DKP (Soğuk Haddelenmiş Sac Artığı) | G8: Üretim Fazlası | H8: Parçalanmış | I8: 39.46 | J8: 1659.6 | K8: 34.73 | L8: 57636.81 | M8: 2025-12-25
A9: T-00008 | B9: F-1005 | C9: Firma 1005 San. Tic. Ltd. Şti. | D9: Kocaeli | E9: Demir-Çelik | F9: Standart Dışı Sac / Levha | G9: Kesim/İşleme Artığı | H9: Preslenmiş-Balya | I9: 31.97 | J9: 761.4 | K9: 25.18 | L9: 19172.34 | M9: 2025-11-06
A10: T-00009 | B10: F-1006 | C10: Firma 1006 San. Tic. Ltd. Şti. | D10: Adana | E10: Demir-Çelik | F10: İmalat Artığı Profil | G10: Kesim/İşleme Artığı | H10: Gevşek | I10: 27.94 | J10: 2410.6 | K10: 19.91 | L10: 47995.17 | M10: 2025-08-26
A11: T-00010 | B11: F-1006 | C11: Firma 1006 San. Tic. Ltd. Şti. | D11: Adana | E11: Demir-Çelik | F11: Kalıp Fazlası Parça | G11: Üretim Fazlası | H11: Parçalanmış | I11: 28.59 | J11: 2601.9 | K11: 25.16 | L11: 65463.86 | M11: 2025-08-30
A12: T-00011 | B12: F-1007 | C12: Firma 1007 San. Tic. Ltd. Şti. | D12: Gaziantep | E12: Demir-Çelik | F12: Talaş / Kırpıntı | G12: Temiz | H12: Gevşek | I12: 10.72 | J12: 854 | K12: 9.37 | L12: 8002.27 | M12: 2026-02-23
A13: T-00012 | B13: F-1007 | C13: Firma 1007 San. Tic. Ltd. Şti. | D13: Gaziantep | E13: Demir-Çelik | F13: DKP (Soğuk Haddelenmiş Sac Artığı) | G13: Üretim Fazlası | H13: Gevşek | I13: 37.7 | J13: 1200.5 | K13: 31.52 | L13: 37839.85 | M13: 2026-07-03
... A381: T-00380 | B381: F-1060 | C381: Firma 1060 San. Tic. Ltd. Şti. | D381: Manisa | E381: Demir-Çelik | F381: Standart Dışı Sac / Levha | G381: Standart Dışı Üretim | H381: Gevşek | I381: 32.59 | J381: 438.6 | K381: 20.13 | L381: 8828.2 | M381: 2025-09-24

Sheet Firma_Ozeti
A1: Firma ID | B1: Firma Adı | C1: Şehir | D1: İşlem Sayısı | E1: Toplam Hacim (kg) | F1: Ortalama İşlem Büyüklüğü (kg) | G1: Ortalama Birim Fiyat (TL/kg) | H1: Toplam Ciro (TL) | J1: DAĞILIM İSTATİSTİKLERİ (Toplam Hacim, kg)
A2: F-1001 | B2: Firma 1001 San. Tic. Ltd. Şti. | C2: Gaziantep | D2: =COUNTIF(Ham_Veri!$B$2:$B$381,A2) -> 2 | E2: =SUMIF(Ham_Veri!$B$2:$B$381,A2,Ham_Veri!$J$2:$J$381) -> 2032.5 | F2: =IFERROR(E2/D2,0) -> 1016.25 | G2: =IFERROR(SUMIF(Ham_Veri!$B$2:$B$381,A2,Ham_Veri!$L$2:$L$381)/E2,0) -> 16.260089 | H2: =SUMIF(Ham_Veri!$B$2:$B$381,A2,Ham_Veri!$L$2:$L$381) -> 33048.63 | J2: Minimum | K2: =MIN(E2:E61) -> 300
A3: F-1002 | B3: Firma 1002 San. Tic. Ltd. Şti. | C3: İstanbul | D3: =COUNTIF(Ham_Veri!$B$2:$B$381,A3) -> 2 | E3: =SUMIF(Ham_Veri!$B$2:$B$381,A3,Ham_Veri!$J$2:$J$381) -> 800 | F3: =IFERROR(E3/D3,0) -> 400 | G3: =IFERROR(SUMIF(Ham_Veri!$B$2:$B$381,A3,Ham_Veri!$L$2:$L$381)/E3,0) -> 27.375 | H3: =SUMIF(Ham_Veri!$B$2:$B$381,A3,Ham_Veri!$L$2:$L$381) -> 21900 | J3: 1. Çeyrek (Q1 - %25) | K3: =QUARTILE(E2:E61,1) -> 1378.75
A4: F-1003 | B4: Firma 1003 San. Tic. Ltd. Şti. | C4: İstanbul | D4: =COUNTIF(Ham_Veri!$B$2:$B$381,A4) -> 2 | E4: =SUMIF(Ham_Veri!$B$2:$B$381,A4,Ham_Veri!$J$2:$J$381) -> 7528.6 | F4: =IFERROR(E4/D4,0) -> 3764.3 | G4: =IFERROR(SUMIF(Ham_Veri!$B$2:$B$381,A4,Ham_Veri!$L$2:$L$381)/E4,0) -> 32.716294 | H4: =SUMIF(Ham_Veri!$B$2:$B$381,A4,Ham_Veri!$L$2:$L$381) -> 246307.89 | J4: Medyan (Q2 - %50) | K4: =QUARTILE(E2:E61,2) -> 3582.55
A5: F-1004 | B5: Firma 1004 San. Tic. Ltd. Şti. | C5: İstanbul | D5: =COUNTIF(Ham_Veri!$B$2:$B$381,A5) -> 1 | E5: =SUMIF(Ham_Veri!$B$2:$B$381,A5,Ham_Veri!$J$2:$J$381) -> 1659.6 | F5: =IFERROR(E5/D5,0) -> 1659.6 | G5: =IFERROR(SUMIF(Ham_Veri!$B$2:$B$381,A5,Ham_Veri!$L$2:$L$381)/E5,0) -> 34.729338 | H5: =SUMIF(Ham_Veri!$B$2:$B$381,A5,Ham_Veri!$L$2:$L$381) -> 57636.81 | J5: 3. Çeyrek (Q3 - %75) | K5: =QUARTILE(E2:E61,3) -> 8974.7
A6: F-1005 | B6: Firma 1005 San. Tic. Ltd. Şti. | C6: Kocaeli | D6: =COUNTIF(Ham_Veri!$B$2:$B$381,A6) -> 1 | E6: =SUMIF(Ham_Veri!$B$2:$B$381,A6,Ham_Veri!$J$2:$J$381) -> 761.4 | F6: =IFERROR(E6/D6,0) -> 761.4 | G6: =IFERROR(SUMIF(Ham_Veri!$B$2:$B$381,A6,Ham_Veri!$L$2:$L$381)/E6,0) -> 25.180378 | H6: =SUMIF(Ham_Veri!$B$2:$B$381,A6,Ham_Veri!$L$2:$L$381) -> 19172.34 | J6: Maksimum | K6: =MAX(E2:E61) -> 19369.5
A7: F-1006 | B7: Firma 1006 San. Tic. Ltd. Şti. | C7: Adana | D7: =COUNTIF(Ham_Veri!$B$2:$B$381,A7) -> 2 | E7: =SUMIF(Ham_Veri!$B$2:$B$381,A7,Ham_Veri!$J$2:$J$381) -> 5012.5 | F7: =IFERROR(E7/D7,0) -> 2506.25 | G7: =IFERROR(SUMIF(Ham_Veri!$B$2:$B$381,A7,Ham_Veri!$L$2:$L$381)/E7,0) -> 22.635218 | H7: =SUMIF(Ham_Veri!$B$2:$B$381,A7,Ham_Veri!$L$2:$L$381) -> 113459.03 | J7: Ortalama (Aritmetik) | K7: =AVERAGE(E2:E61) -> 5914.2033
A8: F-1007 | B8: Firma 1007 San. Tic. Ltd. Şti. | C8: Gaziantep | D8: =COUNTIF(Ham_Veri!$B$2:$B$381,A8) -> 4 | E8: =SUMIF(Ham_Veri!$B$2:$B$381,A8,Ham_Veri!$J$2:$J$381) -> 3711 | F8: =IFERROR(E8/D8,0) -> 927.75 | G8: =IFERROR(SUMIF(Ham_Veri!$B$2:$B$381,A8,Ham_Veri!$L$2:$L$381)/E8,0) -> 21.917874 | H8: =SUMIF(Ham_Veri!$B$2:$B$381,A8,Ham_Veri!$L$2:$L$381) -> 81337.23
A9: F-1008 | B9: Firma 1008 San. Tic. Ltd. Şti. | C9: Bursa | D9: =COUNTIF(Ham_Veri!$B$2:$B$381,A9) -> 8 | E9: =SUMIF(Ham_Veri!$B$2:$B$381,A9,Ham_Veri!$J$2:$J$381) -> 6530 | F9: =IFERROR(E9/D9,0) -> 816.25 | G9: =IFERROR(SUMIF(Ham_Veri!$B$2:$B$381,A9,Ham_Veri!$L$2:$L$381)/E9,0) -> 24.188361 | H9: =SUMIF(Ham_Veri!$B$2:$B$381,A9,Ham_Veri!$L$2:$L$381) -> 157950
A10: F-1009 | B10: Firma 1009 San. Tic. Ltd. Şti. | C10: Bursa | D10: =COUNTIF(Ham_Veri!$B$2:$B$381,A10) -> 4 | E10: =SUMIF(Ham_Veri!$B$2:$B$381,A10,Ham_Veri!$J$2:$J$381) -> 2564.6 | F10: =IFERROR(E10/D10,0) -> 641.15 | G10: =IFERROR(SUMIF(Ham_Veri!$B$2:$B$381,A10,Ham_Veri!$L$2:$L$381)/E10,0) -> 18.800834 | H10: =SUMIF(Ham_Veri!$B$2:$B$381,A10,Ham_Veri!$L$2:$L$381) -> 48216.62 | J10: Not: 'Ortalama işlem hacimli firma' tanımı IQR (Q1-Q3) aralığı ile yapılmıştır.
A11: F-1010 | B11: Firma 1010 San. Tic. Ltd. Şti. | C11: İstanbul | D11: =COUNTIF(Ham_Veri!$B$2:$B$381,A11) -> 1 | E11: =SUMIF(Ham_Veri!$B$2:$B$381,A11,Ham_Veri!$J$2:$J$381) -> 1455.7 | F11: =IFERROR(E11/D11,0) -> 1455.7 | G11: =IFERROR(SUMIF(Ham_Veri!$B$2:$B$381,A11,Ham_Veri!$L$2:$L$381)/E11,0) -> 9.0402143 | H11: =SUMIF(Ham_Veri!$B$2:$B$381,A11,Ham_Veri!$L$2:$L$381) -> 13159.84
A12: F-1011 | B12: Firma 1011 San. Tic. Ltd. Şti. | C12: Konya | D12: =COUNTIF(Ham_Veri!$B$2:$B$381,A12) -> 1 | E12: =SUMIF(Ham_Veri!$B$2:$B$381,A12,Ham_Veri!$J$2:$J$381) -> 537.9 | F12: =IFERROR(E12/D12,0) -> 537.9 | G12: =IFERROR(SUMIF(Ham_Veri!$B$2:$B$381,A12,Ham_Veri!$L$2:$L$381)/E12,0) -> 30.849582 | H12: =SUMIF(Ham_Veri!$B$2:$B$381,A12,Ham_Veri!$L$2:$L$381) -> 16593.99
A13: F-1012 | B13: Firma 1012 San. Tic. Ltd. Şti. | C13: Manisa | D13: =COUNTIF(Ham_Veri!$B$2:$B$381,A13) -> 9 | E13: =SUMIF(Ham_Veri!$B$2:$B$381,A13,Ham_Veri!$J$2:$J$381) -> 5234.1 | F13: =IFERROR(E13/D13,0) -> 581.56667 | G13: =IFERROR(SUMIF(Ham_Veri!$B$2:$B$381,A13,Ham_Veri!$L$2:$L$381)/E13,0) -> 26.939096 | H13: =SUMIF(Ham_Veri!$B$2:$B$381,A13,Ham_Veri!$L$2:$L$381) -> 141001.92
A14: F-1013 | B14: Firma 1013 San. Tic. Ltd. Şti. | C14: Sakarya | D14: =COUNTIF(Ham_Veri!$B$2:$B$381,A14) -> 10 | E14: =SUMIF(Ham_Veri!$B$2:$B$381,A14,Ham_Veri!$J$2:$J$381) -> 5656.8 | F14: =IFERROR(E14/D14,0) -> 565.68 | G14: =IFERROR(SUMIF(Ham_Veri!$B$2:$B$381,A14,Ham_Veri!$L$2:$L$381)/E14,0) -> 21.483595 | H14: =SUMIF(Ham_Veri!$B$2:$B$381,A14,Ham_Veri!$L$2:$L$381) -> 121528.4
A15: F-1014 | B15: Firma 1014 San. Tic. Ltd. Şti. | C15: Eskişehir | D15: =COUNTIF(Ham_Veri!$B$2:$B$381,A15) -> 1 | E15: =SUMIF(Ham_Veri!$B$2:$B$381,A15,Ham_Veri!$J$2:$J$381) -> 300 | F15: =IFERROR(E15/D15,0) -> 300 | G15: =IFERROR(SUMIF(Ham_Veri!$B$2:$B$381,A15,Ham_Veri!$L$2:$L$381)/E15,0) -> 28.26 | H15: =SUMIF(Ham_Veri!$B$2:$B$381,A15,Ham_Veri!$L$2:$L$381) -> 8478
A16: F-1015 | B16: Firma 1015 San. Tic. Ltd. Şti. | C16: İzmir | D16: =COUNTIF(Ham_Veri!$B$2:$B$381,A16) -> 8 | E16: =SUMIF(Ham_Veri!$B$2:$B$381,A16,Ham_Veri!$J$2:$J$381) -> 11921.5 | F16: =IFERROR(E16/D16,0) -> 1490.1875 | G16: =IFERROR(SUMIF(Ham_Veri!$B$2:$B$381,A16,Ham_Veri!$L$2:$L$381)/E16,0) -> 23.123634 | H16: =SUMIF(Ham_Veri!$B$2:$B$381,A16,Ham_Veri!$L$2:$L$381) -> 275668.4
A17: F-1016 | B17: Firma 1016 San. Tic. Ltd. Şti. | C17: İzmir | D17: =COUNTIF(Ham_Veri!$B$2:$B$381,A17) -> 1 | E17: =SUMIF(Ham_Veri!$B$2:$B$381,A17,Ham_Veri!$J$2:$J$381) -> 2161.9 | F17: =IFERROR(E17/D17,0) -> 2161.9 | G17: =IFERROR(SUMIF(Ham_Veri!$B$2:$B$381,A17,Ham_Veri!$L$2:$L$381)/E17,0) -> 24.669434 | H17: =SUMIF(Ham_Veri!$B$2:$B$381,A17,Ham_Veri!$L$2:$L$381) -> 53332.85
A18: F-1017 | B18: Firma 1017 San. Tic. Ltd. Şti. | C18: İzmir | D18: =COUNTIF(Ham_Veri!$B$2:$B$381,A18) -> 22 | E18: =SUMIF(Ham_Veri!$B$2:$B$381,A18,Ham_Veri!$J$2:$J$381) -> 19369.5 | F18: =IFERROR(E18/D18,0) -> 880.43182 | G18: =IFERROR(SUMIF(Ham_Veri!$B$2:$B$381,A18,Ham_Veri!$L$2:$L$381)/E18,0) -> 22.381418 | H18: =SUMIF(Ham_Veri!$B$2:$B$381,A18,Ham_Veri!$L$2:$L$381) -> 433516.88
A19: F-1018 | B19: Firma 1018 San. Tic. Ltd. Şti. | C19: Manisa | D19: =COUNTIF(Ham_Veri!$B$2:$B$381,A19) -> 11 | E19: =SUMIF(Ham_Veri!$B$2:$B$381,A19,Ham_Veri!$J$2:$J$381) -> 11593.4 | F19: =IFERROR(E19/D19,0) -> 1053.9455 | G19: =IFERROR(SUMIF(Ham_Veri!$B$2:$B$381,A19,Ham_Veri!$L$2:$L$381)/E19,0) -> 26.85348 | H19: =SUMIF(Ham_Veri!$B$2:$B$381,A19,Ham_Veri!$L$2:$L$381) -> 311323.14
A20: F-1019 | B20: Firma 1019 San. Tic. Ltd. Şti. | C20: Konya | D20: =COUNTIF(Ham_Veri!$B$2:$B$381,A20) -> 4 | E20: =SUMIF(Ham_Veri!$B$2:$B$381,A20,Ham_Veri!$J$2:$J$381) -> 3133.9 | F20: =IFERROR(E20/D20,0) -> 783.475 | G20: =IFERROR(SUMIF(Ham_Veri!$B$2:$B$381,A20,Ham_Veri!$L$2:$L$381)/E20,0) -> 22.1124 | H20: =SUMIF(Ham_Veri!$B$2:$B$381,A20,Ham_Veri!$L$2:$L$381) -> 69298.05
A21: F-1020 | B21: Firma 1020 San. Tic. Ltd. Şti. | C21: İstanbul | D21: =COUNTIF(Ham_Veri!$B$2:$B$381,A21) -> 1 | E21: =SUMIF(Ham_Veri!$B$2:$B$381,A21,Ham_Veri!$J$2:$J$381) -> 3000 | F21: =IFERROR(E21/D21,0) -> 3000 | G21: =IFERROR(SUMIF(Ham_Veri!$B$2:$B$381,A21,Ham_Veri!$L$2:$L$381)/E21,0) -> 10.11 | H21: =SUMIF(Ham_Veri!$B$2:$B$381,A21,Ham_Veri!$L$2:$L$381) -> 30330
A22: F-1021 | B22: Firma 1021 San. Tic. Ltd. Şti. | C22: İzmir | D22: =COUNTIF(Ham_Veri!$B$2:$B$381,A22) -> 3 | E22: =SUMIF(Ham_Veri!$B$2:$B$381,A22,Ham_Veri!$J$2:$J$381) -> 2760.3 | F22: =IFERROR(E22/D22,0) -> 920.1 | G22: =IFERROR(SUMIF(Ham_Veri!$B$2:$B$381,A22,Ham_Veri!$L$2:$L$381)/E22,0) -> 23.935782 | H22: =SUMIF(Ham_Veri!$B$2:$B$381,A22,Ham_Veri!$L$2:$L$381) -> 66069.94
... A61: F-1060 | B61: Firma 1060 San. Tic. Ltd. Şti. | C61: Manisa | D61: =COUNTIF(Ham_Veri!$B$2:$B$381,A61) -> 1 | E61: =SUMIF(Ham_Veri!$B$2:$B$381,A61,Ham_Veri!$J$2:$J$381) -> 438.6 | F61: =IFERROR(E61/D61,0) -> 438.6 | G61: =IFERROR(SUMIF(Ham_Veri!$B$2:$B$381,A61,Ham_Veri!$L$2:$L$381)/E61,0) -> 20.128135 | H61: =SUMIF(Ham_Veri!$B$2:$B$381,A61,Ham_Veri!$L$2:$L$381) -> 8828.2

Sheet Ortalama_Hacimli_Firmalar
A1: Filtre: Toplam Hacim, Firma_Ozeti sekmesindeki Q1-Q3 (IQR) aralığında olan firmalar
A3: Firma ID | B3: Firma Adı | C3: Şehir | D3: İşlem Sayısı | E3: Toplam Hacim (kg) | F3: Ort. Birim Fiyat (TL/kg) | G3: Toplam Ciro (TL) | H3: Hacim Segmenti
A4: =Firma_Ozeti!A39 -> F-1038 | B4: =Firma_Ozeti!B39 -> Firma 1038 San. Tic. Ltd. Şti. | C4: =Firma_Ozeti!C39 -> Gaziantep | D4: =Firma_Ozeti!D39 -> 12 | E4: =Firma_Ozeti!E39 -> 8897.2 | F4: =Firma_Ozeti!G39 -> 25.648349 | G4: =Firma_Ozeti!H39 -> 228198.49 | H4: Ortalama
A5: =Firma_Ozeti!A32 -> F-1031 | B5: =Firma_Ozeti!B32 -> Firma 1031 San. Tic. Ltd. Şti. | C5: =Firma_Ozeti!C32 -> Manisa | D5: =Firma_Ozeti!D32 -> 8 | E5: =Firma_Ozeti!E32 -> 8425.5 | F5: =Firma_Ozeti!G32 -> 29.081443 | G5: =Firma_Ozeti!H32 -> 245025.7 | H5: Ortalama
A6: =Firma_Ozeti!A4 -> F-1003 | B6: =Firma_Ozeti!B4 -> Firma 1003 San. Tic. Ltd. Şti. | C6: =Firma_Ozeti!C4 -> İstanbul | D6: =Firma_Ozeti!D4 -> 2 | E6: =Firma_Ozeti!E4 -> 7528.6 | F6: =Firma_Ozeti!G4 -> 32.716294 | G6: =Firma_Ozeti!H4 -> 246307.89 | H6: Ortalama
A7: =Firma_Ozeti!A51 -> F-1050 | B7: =Firma_Ozeti!B51 -> Firma 1050 San. Tic. Ltd. Şti. | C7: =Firma_Ozeti!C51 -> Manisa | D7: =Firma_Ozeti!D51 -> 7 | E7: =Firma_Ozeti!E51 -> 7443.6 | F7: =Firma_Ozeti!G51 -> 26.831047 | G7: =Firma_Ozeti!H51 -> 199719.58 | H7: Ortalama
A8: =Firma_Ozeti!A9 -> F-1008 | B8: =Firma_Ozeti!B9 -> Firma 1008 San. Tic. Ltd. Şti. | C8: =Firma_Ozeti!C9 -> Bursa | D8: =Firma_Ozeti!D9 -> 8 | E8: =Firma_Ozeti!E9 -> 6530 | F8: =Firma_Ozeti!G9 -> 24.188361 | G8: =Firma_Ozeti!H9 -> 157950 | H8: Ortalama
A9: =Firma_Ozeti!A49 -> F-1048 | B9: =Firma_Ozeti!B49 -> Firma 1048 San. Tic. Ltd. Şti. | C9: =Firma_Ozeti!C49 -> Manisa | D9: =Firma_Ozeti!D49 -> 8 | E9: =Firma_Ozeti!E49 -> 6468.5 | F9: =Firma_Ozeti!G49 -> 29.600218 | G9: =Firma_Ozeti!H49 -> 191469.01 | H9: Ortalama
A10: =Firma_Ozeti!A28 -> F-1027 | B10: =Firma_Ozeti!B28 -> Firma 1027 San. Tic. Ltd. Şti. | C10: =Firma_Ozeti!C28 -> Manisa | D10: =Firma_Ozeti!D28 -> 8 | E10: =Firma_Ozeti!E28 -> 5985.5 | F10: =Firma_Ozeti!G28 -> 22.492776 | G10: =Firma_Ozeti!H28 -> 134630.51 | H10: Ortalama
A11: =Firma_Ozeti!A37 -> F-1036 | B11: =Firma_Ozeti!B37 -> Firma 1036 San. Tic. Ltd. Şti. | C11: =Firma_Ozeti!C37 -> İstanbul | D11: =Firma_Ozeti!D37 -> 9 | E11: =Firma_Ozeti!E37 -> 5850.2 | F11: =Firma_Ozeti!G37 -> 22.449716 | G11: =Firma_Ozeti!H37 -> 131335.33 | H11: Ortalama
A12: =Firma_Ozeti!A14 -> F-1013 | B12: =Firma_Ozeti!B14 -> Firma 1013 San. Tic. Ltd. Şti. | C12: =Firma_Ozeti!C14 -> Sakarya | D12: =Firma_Ozeti!D14 -> 10 | E12: =Firma_Ozeti!E14 -> 5656.8 | F12: =Firma_Ozeti!G14 -> 21.483595 | G12: =Firma_Ozeti!H14 -> 121528.4 | H12: Ortalama
A13: =Firma_Ozeti!A13 -> F-1012 | B13: =Firma_Ozeti!B13 -> Firma 1012 San. Tic. Ltd. Şti. | C13: =Firma_Ozeti!C13 -> Manisa | D13: =Firma_Ozeti!D13 -> 9 | E13: =Firma_Ozeti!E13 -> 5234.1 | F13: =Firma_Ozeti!G13 -> 26.939096 | G13: =Firma_Ozeti!H13 -> 141001.92 | H13: Ortalama
A14: =Firma_Ozeti!A7 -> F-1006 | B14: =Firma_Ozeti!B7 -> Firma 1006 San. Tic. Ltd. Şti. | C14: =Firma_Ozeti!C7 -> Adana | D14: =Firma_Ozeti!D7 -> 2 | E14: =Firma_Ozeti!E7 -> 5012.5 | F14: =Firma_Ozeti!G7 -> 22.635218 | G14: =Firma_Ozeti!H7 -> 113459.03 | H14: Ortalama
A15: =Firma_Ozeti!A30 -> F-1029 | B15: =Firma_Ozeti!B30 -> Firma 1029 San. Tic. Ltd. Şti. | C15: =Firma_Ozeti!C30 -> Sakarya | D15: =Firma_Ozeti!D30 -> 4 | E15: =Firma_Ozeti!E30 -> 4864 | F15: =Firma_Ozeti!G30 -> 26.630269 | G15: =Firma_Ozeti!H30 -> 129529.63 | H15: Ortalama
A16: =Firma_Ozeti!A40 -> F-1039 | B16: =Firma_Ozeti!B40 -> Firma 1039 San. Tic. Ltd. Şti. | C16: =Firma_Ozeti!C40 -> Gaziantep | D16: =Firma_Ozeti!D40 -> 3 | E16: =Firma_Ozeti!E40 -> 3942.4 | F16: =Firma_Ozeti!G40 -> 22.819871 | G16: =Firma_Ozeti!H40 -> 89965.06 | H16: Ortalama
A17: =Firma_Ozeti!A8 -> F-1007 | B17: =Firma_Ozeti!B8 -> Firma 1007 San. Tic. Ltd. Şti. | C17: =Firma_Ozeti!C8 -> Gaziantep | D17: =Firma_Ozeti!D8 -> 4 | E17: =Firma_Ozeti!E8 -> 3711 | F17: =Firma_Ozeti!G8 -> 21.917874 | G17: =Firma_Ozeti!H8 -> 81337.23 | H17: Ortalama
A18: =Firma_Ozeti!A55 -> F-1054 | B18: =Firma_Ozeti!B55 -> Firma 1054 San. Tic. Ltd. Şti. | C18: =Firma_Ozeti!C55 -> Konya | D18: =Firma_Ozeti!D55 -> 4 | E18: =Firma_Ozeti!E55 -> 3590.1 | F18: =Firma_Ozeti!G55 -> 27.720907 | G18: =Firma_Ozeti!H55 -> 99520.83 | H18: Ortalama
A19: =Firma_Ozeti!A56 -> F-1055 | B19: =Firma_Ozeti!B56 -> Firma 1055 San. Tic. Ltd. Şti. | C19: =Firma_Ozeti!C56 -> İstanbul | D19: =Firma_Ozeti!D56 -> 2 | E19: =Firma_Ozeti!E56 -> 3575 | F19: =Firma_Ozeti!G56 -> 21.956747 | G19: =Firma_Ozeti!H56 -> 78495.37 | H19: Ortalama
A20: =Firma_Ozeti!A38 -> F-1037 | B20: =Firma_Ozeti!B38 -> Firma 1037 San. Tic. Ltd. Şti. | C20: =Firma_Ozeti!C38 -> Gaziantep | D20: =Firma_Ozeti!D38 -> 4 | E20: =Firma_Ozeti!E38 -> 3419.6 | F20: =Firma_Ozeti!G38 -> 29.230574 | G20: =Firma_Ozeti!H38 -> 99956.87 | H20: Ortalama
A21: =Firma_Ozeti!A20 -> F-1019 | B21: =Firma_Ozeti!B20 -> Firma 1019 San. Tic. Ltd. Şti. | C21: =Firma_Ozeti!C20 -> Konya | D21: =Firma_Ozeti!D20 -> 4 | E21: =Firma_Ozeti!E20 -> 3133.9 | F21: =Firma_Ozeti!G20 -> 22.1124 | G21: =Firma_Ozeti!H20 -> 69298.05 | H21: Ortalama
A22: =Firma_Ozeti!A21 -> F-1020 | B22: =Firma_Ozeti!B21 -> Firma 1020 San. Tic. Ltd. Şti. | C22: =Firma_Ozeti!C21 -> İstanbul | D22: =Firma_Ozeti!D21 -> 1 | E22: =Firma_Ozeti!E21 -> 3000 | F22: =Firma_Ozeti!G21 -> 10.11 | G22: =Firma_Ozeti!H21 -> 30330 | H22: Ortalama
A23: =Firma_Ozeti!A46 -> F-1045 | B23: =Firma_Ozeti!B46 -> Firma 1045 San. Tic. Ltd. Şti. | C23: =Firma_Ozeti!C46 -> İstanbul | D23: =Firma_Ozeti!D46 -> 3 | E23: =Firma_Ozeti!E46 -> 3000 | F23: =Firma_Ozeti!G46 -> 26.81857 | G23: =Firma_Ozeti!H46 -> 80455.71 | H23: Ortalama
A24: =Firma_Ozeti!A22 -> F-1021 | B24: =Firma_Ozeti!B22 -> Firma 1021 San. Tic. Ltd. Şti. | C24: =Firma_Ozeti!C22 -> İzmir | D24: =Firma_Ozeti!D22 -> 3 | E24: =Firma_Ozeti!E22 -> 2760.3 | F24: =Firma_Ozeti!G22 -> 23.935782 | G24: =Firma_Ozeti!H22 -> 66069.94 | H24: Ortalama
A25: =Firma_Ozeti!A35 -> F-1034 | B25: =Firma_Ozeti!B35 -> Firma 1034 San. Tic. Ltd. Şti. | C25: =Firma_Ozeti!C35 -> Eskişehir | D25: =Firma_Ozeti!D35 -> 3 | E25: =Firma_Ozeti!E35 -> 2700.7 | F25: =Firma_Ozeti!G35 -> 18.226112 | G25: =Firma_Ozeti!H35 -> 49223.26 | H25: Ortalama
A26: =Firma_Ozeti!A10 -> F-1009 | B26: =Firma_Ozeti!B10 -> Firma 1009 San. Tic. Ltd. Şti. | C26: =Firma_Ozeti!C10 -> Bursa | D26: =Firma_Ozeti!D10 -> 4 | E26: =Firma_Ozeti!E10 -> 2564.6 | F26: =Firma_Ozeti!G10 -> 18.800834 | G26: =Firma_Ozeti!H10 -> 48216.62 | H26: Ortalama
A27: =Firma_Ozeti!A58 -> F-1057 | B27: =Firma_Ozeti!B58 -> Firma 1057 San. Tic. Ltd. Şti. | C27: =Firma_Ozeti!C58 -> İzmir | D27: =Firma_Ozeti!D58 -> 5 | E27: =Firma_Ozeti!E58 -> 2520 | F27: =Firma_Ozeti!G58 -> 19.511357 | G27: =Firma_Ozeti!H58 -> 49168.62 | H27: Ortalama
A28: =Firma_Ozeti!A17 -> F-1016 | B28: =Firma_Ozeti!B17 -> Firma 1016 San. Tic. Ltd. Şti. | C28: =Firma_Ozeti!C17 -> İzmir | D28: =Firma_Ozeti!D17 -> 1 | E28: =Firma_Ozeti!E17 -> 2161.9 | F28: =Firma_Ozeti!G17 -> 24.669434 | G28: =Firma_Ozeti!H17 -> 53332.85 | H28: Ortalama
A29: =Firma_Ozeti!A2 -> F-1001 | B29: =Firma_Ozeti!B2 -> Firma 1001 San. Tic. Ltd. Şti. | C29: =Firma_Ozeti!C2 -> Gaziantep | D29: =Firma_Ozeti!D2 -> 2 | E29: =Firma_Ozeti!E2 -> 2032.5 | F29: =Firma_Ozeti!G2 -> 16.260089 | G29: =Firma_Ozeti!H2 -> 33048.63 | H29: Ortalama
A30: =Firma_Ozeti!A5 -> F-1004 | B30: =Firma_Ozeti!B5 -> Firma 1004 San. Tic. Ltd. Şti. | C30: =Firma_Ozeti!C5 -> İstanbul | D30: =Firma_Ozeti!D5 -> 1 | E30: =Firma_Ozeti!E5 -> 1659.6 | F30: =Firma_Ozeti!G5 -> 34.729338 | G30: =Firma_Ozeti!H5 -> 57636.81 | H30: Ortalama
A31: =Firma_Ozeti!A26 -> F-1025 | B31: =Firma_Ozeti!B26 -> Firma 1025 San. Tic. Ltd. Şti. | C31: =Firma_Ozeti!C26 -> Eskişehir | D31: =Firma_Ozeti!D26 -> 2 | E31: =Firma_Ozeti!E26 -> 1616.4 | F31: =Firma_Ozeti!G26 -> 24.519983 | G31: =Firma_Ozeti!H26 -> 39634.1 | H31: Ortalama
A32: =Firma_Ozeti!A44 -> F-1043 | B32: =Firma_Ozeti!B44 -> Firma 1043 San. Tic. Ltd. Şti. | C32: =Firma_Ozeti!C44 -> Adana | D32: =Firma_Ozeti!D44 -> 1 | E32: =Firma_Ozeti!E44 -> 1472.8 | F32: =Firma_Ozeti!G44 -> 19.330079 | G32: =Firma_Ozeti!H44 -> 28469.34 | H32: Ortalama
A33: =Firma_Ozeti!A11 -> F-1010 | B33: =Firma_Ozeti!B11 -> Firma 1010 San. Tic. Ltd. Şti. | C33: =Firma_Ozeti!C11 -> İstanbul | D33: =Firma_Ozeti!D11 -> 1 | E33: =Firma_Ozeti!E11 -> 1455.7 | F33: =Firma_Ozeti!G11 -> 9.0402143 | G33: =Firma_Ozeti!H11 -> 13159.84 | H33: Ortalama
A36: ÖZET VE ÇEVRESEL ETKİ (Ortalama Hacimli Firmalar)
A37: Filtreye Giren Firma Sayısı | B37: =COUNTA(A4:A33) -> 30
A38: Toplam İşlem Hacmi (kg) | B38: =SUM(E4:E33) -> 126213
A39: Toplam İşlem Hacmi (ton) | B39: =SUM(E4:E33)/1000 -> 126.213
A40: Toplam Ciro (TL) | B40: =SUM(G4:G33) -> 3107474.6
A41: Ortalama Birim Fiyat (TL/kg) | B41: =AVERAGE(F4:F33) -> 23.413552
A43: ÇEVRESEL ETKİ — ÖNLENEN BİRİNCİL ÜRETİM
A44: Bu malzemeler platformda satılmasaydı hurdaya ayrılıp SONRADAN eritilerek geri kazanılması gerekecekti. Doğrudan yeniden kullanım, hem hurdaya gitmeyi hem de yeniden eritme (birincil üretim) sürecini baştan önler.
...
